
import React, { createContext, useContext, useEffect, useState } from 'react';
import { Session, User } from '@supabase/supabase-js';
import { supabase } from '@/integrations/supabase/client';
import { useNavigate } from 'react-router-dom';
import { toast } from '@/components/ui/use-toast';

type AuthContextType = {
  session: Session | null;
  user: User | null;
  loading: boolean;
  signIn: (email: string, password: string) => Promise<void>;
  signUp: (email: string, password: string, fullName: string) => Promise<void>;
  signOut: () => Promise<void>;
  sendPasswordResetEmail: (email: string) => Promise<void>; // Add type for reset function
};

const AuthContext = createContext<AuthContextType | undefined>(undefined);

export const AuthProvider: React.FC<{ children: React.ReactNode }> = ({ children }) => {
  const [session, setSession] = useState<Session | null>(null);
  const [user, setUser] = useState<User | null>(null);
  const [loading, setLoading] = useState(true);
  const navigate = useNavigate();

  useEffect(() => {
    const { data: { subscription } } = supabase.auth.onAuthStateChange(
      (event, session) => {
        setSession(session);
        setUser(session?.user ?? null);
      }
    );

    supabase.auth.getSession().then(({ data: { session } }) => {
      setSession(session);
      setUser(session?.user ?? null);
      setLoading(false);
    });

    return () => subscription.unsubscribe();
  }, []);

  const signIn = async (email: string, password: string) => {
    try {
      const { error } = await supabase.auth.signInWithPassword({
        email,
        password,
      });

      if (error) {
        toast({
          title: "Login failed",
          description: error.message,
          variant: "destructive",
        });
        throw error;
      }

      toast({
        title: "Success!",
        description: "You've successfully logged in",
      });
      navigate('/dashboard');
    } catch (error) {
      console.error('Error logging in:', error);
      // Re-throw the error so the calling component knows it failed
      throw error;
    }
  };

  const signUp = async (email: string, password: string, fullName: string) => {
    try {
      const { error } = await supabase.auth.signUp({
        email,
        password,
        options: {
          data: {
            full_name: fullName
          },
          emailRedirectTo: `${window.location.origin}/auth/callback`
        }
      });

      if (error) {
        toast({
          title: "Registration failed",
          description: error.message,
          variant: "destructive",
        });
        throw error;
      }

      toast({
        title: "Success!",
        description: "Please check your email to confirm your registration",
      });
    } catch (error) {
      console.error('Error signing up:', error);
      throw error;
    }
};

  const signOut = async () => {
    try {
      const { error } = await supabase.auth.signOut();
      if (error) throw error;
      navigate('/');
    } catch (error) {
      toast({
        title: "Sign out failed",
        description: error instanceof Error ? error.message : "An unknown error occurred",
        variant: "destructive",
      });
      console.error('Error signing out:', error);
      // Don't re-throw, just show toast
    }
  };

  // Function to send password reset email
  const sendPasswordResetEmail = async (email: string) => {
    try {
      const { error } = await supabase.auth.resetPasswordForEmail(email, {
        redirectTo: `${window.location.origin}/update-password`, // Your reset password page URL
      });

      if (error) {
        toast({
          title: "Password Reset Failed",
          description: error.message,
          variant: "destructive",
        });
        throw error;
      }

      toast({
        title: "Password Reset Email Sent",
        description: "Please check your email for instructions to reset your password.",
      });
    } catch (error) {
      console.error('Error sending password reset email:', error);
      // Re-throw the error so the calling component knows it failed
      throw error;
    }
  };

  return (
    <AuthContext.Provider 
      value={{ session, user, loading, signIn, signUp, signOut, sendPasswordResetEmail }} // Add sendPasswordResetEmail to context
    >
      {children}
    </AuthContext.Provider>
  );
};

export const useAuth = () => {
  const context = useContext(AuthContext);
  if (context === undefined) {
    throw new Error('useAuth must be used within an AuthProvider');
  }
  return context;
};
